<robot name="vehicle_blue">
    <link name="chassis">
        <visual>
            <geometry>
                <box size="2.0 1.0 0.5"/>
            </geometry>
            <material name="blue_material">
                <color rgba="0.0 0.0 1.0 1"/>
            </material>
        </visual>
        <collision>
            <geometry>
                <box size="2.0 1.0 0.5"/>
            </geometry>
        </collision>
    </link>

    <link name="left_wheel">
        <visual>
            <geometry>
                <cylinder radius="0.4" length="0.2"/>
            </geometry>
            <material name="red_material">
                <color rgba="1.0 0.0 0.0 1"/>
            </material>
        </visual>
        <collision>
            <geometry>
                <cylinder radius="0.4" length="0.2"/>
            </geometry>
        </collision>
    </link>

    <link name="right_wheel">
        <visual>
            <geometry>
                <cylinder radius="0.4" length="0.2"/>
            </geometry>
            <material name="red_material">
                <color rgba="1.0 0.0 0.0 1"/>
            </material>
        </visual>
        <collision>
            <geometry>
                <cylinder radius="0.4" length="0.2"/>
            </geometry>
        </collision>
    </link>

    <link name="caster">
        <visual>
            <geometry>
                <sphere radius="0.2"/>
            </geometry>
            <material name="green_material">
                <color rgba="0.0 1.0 0.0 1"/>
            </material>
        </visual>
        <collision>
            <geometry>
                <sphere radius="0.2"/>
            </geometry>
        </collision>
    </link>

    <joint name="left_wheel_joint" type="continuous">
        <parent link="chassis"/>
        <child link="left_wheel"/>
        <axis xyz="0 1 0"/>
    </joint>

    <joint name="right_wheel_joint" type="continuous">
        <parent link="chassis"/>
        <child link="right_wheel"/>
        <axis xyz="0 1 0"/>
    </joint>

    <joint name="caster_joint" type="continuous">
        <parent link="chassis"/>
        <child link="caster"/>
        <axis xyz="0 0 1"/>
    </joint>
</robot>
